terminate called after throwing an instance of 'cl::Error'
  what():  clCreateContext
